Backup failed for Site glbalbrands.com. Database or site_config.json may be corrupted
Traceback (most recent call last):
  File "apps/frappe/frappe/commands/site.py", line 686, in backup
    odb = scheduled_backup(
  File "apps/frappe/frappe/utils/backups.py", line 538, in scheduled_backup
    odb = new_backup(
  File "apps/frappe/frappe/utils/backups.py", line 572, in new_backup
    odb = BackupGenerator(
  File "apps/frappe/frappe/utils/backups.py", line 86, in __init__
    self.setup_backup_tables()
  File "apps/frappe/frappe/utils/backups.py", line 120, in setup_backup_tables
    existing_tables = frappe.db.get_tables()
  File "apps/frappe/frappe/database/database.py", line 1013, in get_tables
    table_rows = self.sql(
  File "apps/frappe/frappe/database/database.py", line 161, in sql
    self.connect()
  File "apps/frappe/frappe/database/database.py", line 93, in connect
    self._conn = self.get_connection()
  File "apps/frappe/frappe/database/mariadb/database.py", line 88, in get_connection
    conn = pymysql.connect(
  File "env/lib/python3.8/site-packages/pymysql/connections.py", line 353, in __init__
    self.connect()
  File "env/lib/python3.8/site-packages/pymysql/connections.py", line 633, in connect
    self._request_authentication()
  File "env/lib/python3.8/site-packages/pymysql/connections.py", line 907, in _request_authentication
    auth_packet = self._read_packet()
  File "env/lib/python3.8/site-packages/pymysql/connections.py", line 725, in _read_packet
    packet.raise_for_error()
  File "env/lib/python3.8/site-packages/pymysql/protocol.py", line 221, in raise_for_error
    err.raise_mysql_exception(self._data)
  File "env/lib/python3.8/site-packages/pymysql/err.py", line 143, in raise_mysql_exception
    raise errorclass(errno, errval)
pymysql.err.OperationalError: (1045, "Access denied for user '_11d5326f068ed36c'@'localhost' (using password: YES)")

Backup failed for Site globalbrands.com. Database or site_config.json may be corrupted
Traceback (most recent call last):
  File "apps/frappe/frappe/commands/site.py", line 686, in backup
    odb = scheduled_backup(
  File "apps/frappe/frappe/utils/backups.py", line 538, in scheduled_backup
    odb = new_backup(
  File "apps/frappe/frappe/utils/backups.py", line 572, in new_backup
    odb = BackupGenerator(
  File "apps/frappe/frappe/utils/backups.py", line 86, in __init__
    self.setup_backup_tables()
  File "apps/frappe/frappe/utils/backups.py", line 120, in setup_backup_tables
    existing_tables = frappe.db.get_tables()
  File "apps/frappe/frappe/database/database.py", line 1013, in get_tables
    table_rows = self.sql(
  File "apps/frappe/frappe/database/database.py", line 161, in sql
    self.connect()
  File "apps/frappe/frappe/database/database.py", line 93, in connect
    self._conn = self.get_connection()
  File "apps/frappe/frappe/database/mariadb/database.py", line 88, in get_connection
    conn = pymysql.connect(
  File "env/lib/python3.8/site-packages/pymysql/connections.py", line 353, in __init__
    self.connect()
  File "env/lib/python3.8/site-packages/pymysql/connections.py", line 633, in connect
    self._request_authentication()
  File "env/lib/python3.8/site-packages/pymysql/connections.py", line 907, in _request_authentication
    auth_packet = self._read_packet()
  File "env/lib/python3.8/site-packages/pymysql/connections.py", line 725, in _read_packet
    packet.raise_for_error()
  File "env/lib/python3.8/site-packages/pymysql/protocol.py", line 221, in raise_for_error
    err.raise_mysql_exception(self._data)
  File "env/lib/python3.8/site-packages/pymysql/err.py", line 143, in raise_mysql_exception
    raise errorclass(errno, errval)
pymysql.err.OperationalError: (1045, "Access denied for user '_11d5326f068ed36c'@'localhost' (using password: YES)")

Backup failed for Site mysite.com. Database or site_config.json may be corrupted
Traceback (most recent call last):
  File "apps/frappe/frappe/commands/site.py", line 686, in backup
    odb = scheduled_backup(
  File "apps/frappe/frappe/utils/backups.py", line 538, in scheduled_backup
    odb = new_backup(
  File "apps/frappe/frappe/utils/backups.py", line 572, in new_backup
    odb = BackupGenerator(
  File "apps/frappe/frappe/utils/backups.py", line 86, in __init__
    self.setup_backup_tables()
  File "apps/frappe/frappe/utils/backups.py", line 120, in setup_backup_tables
    existing_tables = frappe.db.get_tables()
  File "apps/frappe/frappe/database/database.py", line 1013, in get_tables
    table_rows = self.sql(
  File "apps/frappe/frappe/database/database.py", line 161, in sql
    self.connect()
  File "apps/frappe/frappe/database/database.py", line 93, in connect
    self._conn = self.get_connection()
  File "apps/frappe/frappe/database/mariadb/database.py", line 88, in get_connection
    conn = pymysql.connect(
  File "env/lib/python3.8/site-packages/pymysql/connections.py", line 353, in __init__
    self.connect()
  File "env/lib/python3.8/site-packages/pymysql/connections.py", line 633, in connect
    self._request_authentication()
  File "env/lib/python3.8/site-packages/pymysql/connections.py", line 907, in _request_authentication
    auth_packet = self._read_packet()
  File "env/lib/python3.8/site-packages/pymysql/connections.py", line 725, in _read_packet
    packet.raise_for_error()
  File "env/lib/python3.8/site-packages/pymysql/protocol.py", line 221, in raise_for_error
    err.raise_mysql_exception(self._data)
  File "env/lib/python3.8/site-packages/pymysql/err.py", line 143, in raise_mysql_exception
    raise errorclass(errno, errval)
pymysql.err.OperationalError: (1045, "Access denied for user '_11d5326f068ed36c'@'localhost' (using password: YES)")

Backup failed for Site mysite.localhost. Database or site_config.json may be corrupted
Traceback (most recent call last):
  File "apps/frappe/frappe/commands/site.py", line 686, in backup
    odb = scheduled_backup(
  File "apps/frappe/frappe/utils/backups.py", line 538, in scheduled_backup
    odb = new_backup(
  File "apps/frappe/frappe/utils/backups.py", line 572, in new_backup
    odb = BackupGenerator(
  File "apps/frappe/frappe/utils/backups.py", line 86, in __init__
    self.setup_backup_tables()
  File "apps/frappe/frappe/utils/backups.py", line 120, in setup_backup_tables
    existing_tables = frappe.db.get_tables()
  File "apps/frappe/frappe/database/database.py", line 1013, in get_tables
    table_rows = self.sql(
  File "apps/frappe/frappe/database/database.py", line 161, in sql
    self.connect()
  File "apps/frappe/frappe/database/database.py", line 93, in connect
    self._conn = self.get_connection()
  File "apps/frappe/frappe/database/mariadb/database.py", line 88, in get_connection
    conn = pymysql.connect(
  File "env/lib/python3.8/site-packages/pymysql/connections.py", line 353, in __init__
    self.connect()
  File "env/lib/python3.8/site-packages/pymysql/connections.py", line 633, in connect
    self._request_authentication()
  File "env/lib/python3.8/site-packages/pymysql/connections.py", line 907, in _request_authentication
    auth_packet = self._read_packet()
  File "env/lib/python3.8/site-packages/pymysql/connections.py", line 725, in _read_packet
    packet.raise_for_error()
  File "env/lib/python3.8/site-packages/pymysql/protocol.py", line 221, in raise_for_error
    err.raise_mysql_exception(self._data)
  File "env/lib/python3.8/site-packages/pymysql/err.py", line 143, in raise_mysql_exception
    raise errorclass(errno, errval)
pymysql.err.OperationalError: (1045, "Access denied for user '_11d5326f068ed36c'@'localhost' (using password: YES)")

Backup failed for Site testsite.com. Database or site_config.json may be corrupted
Traceback (most recent call last):
  File "apps/frappe/frappe/commands/site.py", line 686, in backup
    odb = scheduled_backup(
  File "apps/frappe/frappe/utils/backups.py", line 538, in scheduled_backup
    odb = new_backup(
  File "apps/frappe/frappe/utils/backups.py", line 572, in new_backup
    odb = BackupGenerator(
  File "apps/frappe/frappe/utils/backups.py", line 86, in __init__
    self.setup_backup_tables()
  File "apps/frappe/frappe/utils/backups.py", line 120, in setup_backup_tables
    existing_tables = frappe.db.get_tables()
  File "apps/frappe/frappe/database/database.py", line 1013, in get_tables
    table_rows = self.sql(
  File "apps/frappe/frappe/database/database.py", line 161, in sql
    self.connect()
  File "apps/frappe/frappe/database/database.py", line 93, in connect
    self._conn = self.get_connection()
  File "apps/frappe/frappe/database/mariadb/database.py", line 88, in get_connection
    conn = pymysql.connect(
  File "env/lib/python3.8/site-packages/pymysql/connections.py", line 353, in __init__
    self.connect()
  File "env/lib/python3.8/site-packages/pymysql/connections.py", line 633, in connect
    self._request_authentication()
  File "env/lib/python3.8/site-packages/pymysql/connections.py", line 907, in _request_authentication
    auth_packet = self._read_packet()
  File "env/lib/python3.8/site-packages/pymysql/connections.py", line 725, in _read_packet
    packet.raise_for_error()
  File "env/lib/python3.8/site-packages/pymysql/protocol.py", line 221, in raise_for_error
    err.raise_mysql_exception(self._data)
  File "env/lib/python3.8/site-packages/pymysql/err.py", line 143, in raise_mysql_exception
    raise errorclass(errno, errval)
pymysql.err.OperationalError: (1045, "Access denied for user '_11d5326f068ed36c'@'localhost' (using password: YES)")

Backup failed for Site testsite2.com. Database or site_config.json may be corrupted
Traceback (most recent call last):
  File "apps/frappe/frappe/commands/site.py", line 686, in backup
    odb = scheduled_backup(
  File "apps/frappe/frappe/utils/backups.py", line 538, in scheduled_backup
    odb = new_backup(
  File "apps/frappe/frappe/utils/backups.py", line 572, in new_backup
    odb = BackupGenerator(
  File "apps/frappe/frappe/utils/backups.py", line 86, in __init__
    self.setup_backup_tables()
  File "apps/frappe/frappe/utils/backups.py", line 120, in setup_backup_tables
    existing_tables = frappe.db.get_tables()
  File "apps/frappe/frappe/database/database.py", line 1013, in get_tables
    table_rows = self.sql(
  File "apps/frappe/frappe/database/database.py", line 161, in sql
    self.connect()
  File "apps/frappe/frappe/database/database.py", line 93, in connect
    self._conn = self.get_connection()
  File "apps/frappe/frappe/database/mariadb/database.py", line 88, in get_connection
    conn = pymysql.connect(
  File "env/lib/python3.8/site-packages/pymysql/connections.py", line 353, in __init__
    self.connect()
  File "env/lib/python3.8/site-packages/pymysql/connections.py", line 633, in connect
    self._request_authentication()
  File "env/lib/python3.8/site-packages/pymysql/connections.py", line 907, in _request_authentication
    auth_packet = self._read_packet()
  File "env/lib/python3.8/site-packages/pymysql/connections.py", line 725, in _read_packet
    packet.raise_for_error()
  File "env/lib/python3.8/site-packages/pymysql/protocol.py", line 221, in raise_for_error
    err.raise_mysql_exception(self._data)
  File "env/lib/python3.8/site-packages/pymysql/err.py", line 143, in raise_mysql_exception
    raise errorclass(errno, errval)
pymysql.err.OperationalError: (1045, "Access denied for user '_11d5326f068ed36c'@'localhost' (using password: YES)")

Backup failed for Site testsite3.com. Database or site_config.json may be corrupted
Traceback (most recent call last):
  File "apps/frappe/frappe/commands/site.py", line 686, in backup
    odb = scheduled_backup(
  File "apps/frappe/frappe/utils/backups.py", line 538, in scheduled_backup
    odb = new_backup(
  File "apps/frappe/frappe/utils/backups.py", line 572, in new_backup
    odb = BackupGenerator(
  File "apps/frappe/frappe/utils/backups.py", line 86, in __init__
    self.setup_backup_tables()
  File "apps/frappe/frappe/utils/backups.py", line 120, in setup_backup_tables
    existing_tables = frappe.db.get_tables()
  File "apps/frappe/frappe/database/database.py", line 1013, in get_tables
    table_rows = self.sql(
  File "apps/frappe/frappe/database/database.py", line 161, in sql
    self.connect()
  File "apps/frappe/frappe/database/database.py", line 93, in connect
    self._conn = self.get_connection()
  File "apps/frappe/frappe/database/mariadb/database.py", line 88, in get_connection
    conn = pymysql.connect(
  File "env/lib/python3.8/site-packages/pymysql/connections.py", line 353, in __init__
    self.connect()
  File "env/lib/python3.8/site-packages/pymysql/connections.py", line 633, in connect
    self._request_authentication()
  File "env/lib/python3.8/site-packages/pymysql/connections.py", line 907, in _request_authentication
    auth_packet = self._read_packet()
  File "env/lib/python3.8/site-packages/pymysql/connections.py", line 725, in _read_packet
    packet.raise_for_error()
  File "env/lib/python3.8/site-packages/pymysql/protocol.py", line 221, in raise_for_error
    err.raise_mysql_exception(self._data)
  File "env/lib/python3.8/site-packages/pymysql/err.py", line 143, in raise_mysql_exception
    raise errorclass(errno, errval)
pymysql.err.OperationalError: (1045, "Access denied for user '_11d5326f068ed36c'@'localhost' (using password: YES)")

Backup failed for Site glbalbrands.com. Database or site_config.json may be corrupted
Traceback (most recent call last):
  File "apps/frappe/frappe/commands/site.py", line 686, in backup
    odb = scheduled_backup(
  File "apps/frappe/frappe/utils/backups.py", line 538, in scheduled_backup
    odb = new_backup(
  File "apps/frappe/frappe/utils/backups.py", line 572, in new_backup
    odb = BackupGenerator(
  File "apps/frappe/frappe/utils/backups.py", line 86, in __init__
    self.setup_backup_tables()
  File "apps/frappe/frappe/utils/backups.py", line 120, in setup_backup_tables
    existing_tables = frappe.db.get_tables()
  File "apps/frappe/frappe/database/database.py", line 1013, in get_tables
    table_rows = self.sql(
  File "apps/frappe/frappe/database/database.py", line 161, in sql
    self.connect()
  File "apps/frappe/frappe/database/database.py", line 93, in connect
    self._conn = self.get_connection()
  File "apps/frappe/frappe/database/mariadb/database.py", line 88, in get_connection
    conn = pymysql.connect(
  File "env/lib/python3.8/site-packages/pymysql/connections.py", line 353, in __init__
    self.connect()
  File "env/lib/python3.8/site-packages/pymysql/connections.py", line 633, in connect
    self._request_authentication()
  File "env/lib/python3.8/site-packages/pymysql/connections.py", line 907, in _request_authentication
    auth_packet = self._read_packet()
  File "env/lib/python3.8/site-packages/pymysql/connections.py", line 725, in _read_packet
    packet.raise_for_error()
  File "env/lib/python3.8/site-packages/pymysql/protocol.py", line 221, in raise_for_error
    err.raise_mysql_exception(self._data)
  File "env/lib/python3.8/site-packages/pymysql/err.py", line 143, in raise_mysql_exception
    raise errorclass(errno, errval)
pymysql.err.OperationalError: (1045, "Access denied for user '_11d5326f068ed36c'@'localhost' (using password: YES)")

Backup failed for Site globalbrands.com. Database or site_config.json may be corrupted
Traceback (most recent call last):
  File "apps/frappe/frappe/commands/site.py", line 686, in backup
    odb = scheduled_backup(
  File "apps/frappe/frappe/utils/backups.py", line 538, in scheduled_backup
    odb = new_backup(
  File "apps/frappe/frappe/utils/backups.py", line 572, in new_backup
    odb = BackupGenerator(
  File "apps/frappe/frappe/utils/backups.py", line 86, in __init__
    self.setup_backup_tables()
  File "apps/frappe/frappe/utils/backups.py", line 120, in setup_backup_tables
    existing_tables = frappe.db.get_tables()
  File "apps/frappe/frappe/database/database.py", line 1013, in get_tables
    table_rows = self.sql(
  File "apps/frappe/frappe/database/database.py", line 161, in sql
    self.connect()
  File "apps/frappe/frappe/database/database.py", line 93, in connect
    self._conn = self.get_connection()
  File "apps/frappe/frappe/database/mariadb/database.py", line 88, in get_connection
    conn = pymysql.connect(
  File "env/lib/python3.8/site-packages/pymysql/connections.py", line 353, in __init__
    self.connect()
  File "env/lib/python3.8/site-packages/pymysql/connections.py", line 633, in connect
    self._request_authentication()
  File "env/lib/python3.8/site-packages/pymysql/connections.py", line 907, in _request_authentication
    auth_packet = self._read_packet()
  File "env/lib/python3.8/site-packages/pymysql/connections.py", line 725, in _read_packet
    packet.raise_for_error()
  File "env/lib/python3.8/site-packages/pymysql/protocol.py", line 221, in raise_for_error
    err.raise_mysql_exception(self._data)
  File "env/lib/python3.8/site-packages/pymysql/err.py", line 143, in raise_mysql_exception
    raise errorclass(errno, errval)
pymysql.err.OperationalError: (1045, "Access denied for user '_11d5326f068ed36c'@'localhost' (using password: YES)")

Backup failed for Site mysite.com. Database or site_config.json may be corrupted
Traceback (most recent call last):
  File "apps/frappe/frappe/commands/site.py", line 686, in backup
    odb = scheduled_backup(
  File "apps/frappe/frappe/utils/backups.py", line 538, in scheduled_backup
    odb = new_backup(
  File "apps/frappe/frappe/utils/backups.py", line 572, in new_backup
    odb = BackupGenerator(
  File "apps/frappe/frappe/utils/backups.py", line 86, in __init__
    self.setup_backup_tables()
  File "apps/frappe/frappe/utils/backups.py", line 120, in setup_backup_tables
    existing_tables = frappe.db.get_tables()
  File "apps/frappe/frappe/database/database.py", line 1013, in get_tables
    table_rows = self.sql(
  File "apps/frappe/frappe/database/database.py", line 161, in sql
    self.connect()
  File "apps/frappe/frappe/database/database.py", line 93, in connect
    self._conn = self.get_connection()
  File "apps/frappe/frappe/database/mariadb/database.py", line 88, in get_connection
    conn = pymysql.connect(
  File "env/lib/python3.8/site-packages/pymysql/connections.py", line 353, in __init__
    self.connect()
  File "env/lib/python3.8/site-packages/pymysql/connections.py", line 633, in connect
    self._request_authentication()
  File "env/lib/python3.8/site-packages/pymysql/connections.py", line 907, in _request_authentication
    auth_packet = self._read_packet()
  File "env/lib/python3.8/site-packages/pymysql/connections.py", line 725, in _read_packet
    packet.raise_for_error()
  File "env/lib/python3.8/site-packages/pymysql/protocol.py", line 221, in raise_for_error
    err.raise_mysql_exception(self._data)
  File "env/lib/python3.8/site-packages/pymysql/err.py", line 143, in raise_mysql_exception
    raise errorclass(errno, errval)
pymysql.err.OperationalError: (1045, "Access denied for user '_11d5326f068ed36c'@'localhost' (using password: YES)")

Backup failed for Site mysite.localhost. Database or site_config.json may be corrupted
Traceback (most recent call last):
  File "apps/frappe/frappe/commands/site.py", line 686, in backup
    odb = scheduled_backup(
  File "apps/frappe/frappe/utils/backups.py", line 538, in scheduled_backup
    odb = new_backup(
  File "apps/frappe/frappe/utils/backups.py", line 572, in new_backup
    odb = BackupGenerator(
  File "apps/frappe/frappe/utils/backups.py", line 86, in __init__
    self.setup_backup_tables()
  File "apps/frappe/frappe/utils/backups.py", line 120, in setup_backup_tables
    existing_tables = frappe.db.get_tables()
  File "apps/frappe/frappe/database/database.py", line 1013, in get_tables
    table_rows = self.sql(
  File "apps/frappe/frappe/database/database.py", line 161, in sql
    self.connect()
  File "apps/frappe/frappe/database/database.py", line 93, in connect
    self._conn = self.get_connection()
  File "apps/frappe/frappe/database/mariadb/database.py", line 88, in get_connection
    conn = pymysql.connect(
  File "env/lib/python3.8/site-packages/pymysql/connections.py", line 353, in __init__
    self.connect()
  File "env/lib/python3.8/site-packages/pymysql/connections.py", line 633, in connect
    self._request_authentication()
  File "env/lib/python3.8/site-packages/pymysql/connections.py", line 907, in _request_authentication
    auth_packet = self._read_packet()
  File "env/lib/python3.8/site-packages/pymysql/connections.py", line 725, in _read_packet
    packet.raise_for_error()
  File "env/lib/python3.8/site-packages/pymysql/protocol.py", line 221, in raise_for_error
    err.raise_mysql_exception(self._data)
  File "env/lib/python3.8/site-packages/pymysql/err.py", line 143, in raise_mysql_exception
    raise errorclass(errno, errval)
pymysql.err.OperationalError: (1045, "Access denied for user '_11d5326f068ed36c'@'localhost' (using password: YES)")

Backup failed for Site testsite.com. Database or site_config.json may be corrupted
Traceback (most recent call last):
  File "apps/frappe/frappe/commands/site.py", line 686, in backup
    odb = scheduled_backup(
  File "apps/frappe/frappe/utils/backups.py", line 538, in scheduled_backup
    odb = new_backup(
  File "apps/frappe/frappe/utils/backups.py", line 572, in new_backup
    odb = BackupGenerator(
  File "apps/frappe/frappe/utils/backups.py", line 86, in __init__
    self.setup_backup_tables()
  File "apps/frappe/frappe/utils/backups.py", line 120, in setup_backup_tables
    existing_tables = frappe.db.get_tables()
  File "apps/frappe/frappe/database/database.py", line 1013, in get_tables
    table_rows = self.sql(
  File "apps/frappe/frappe/database/database.py", line 161, in sql
    self.connect()
  File "apps/frappe/frappe/database/database.py", line 93, in connect
    self._conn = self.get_connection()
  File "apps/frappe/frappe/database/mariadb/database.py", line 88, in get_connection
    conn = pymysql.connect(
  File "env/lib/python3.8/site-packages/pymysql/connections.py", line 353, in __init__
    self.connect()
  File "env/lib/python3.8/site-packages/pymysql/connections.py", line 633, in connect
    self._request_authentication()
  File "env/lib/python3.8/site-packages/pymysql/connections.py", line 907, in _request_authentication
    auth_packet = self._read_packet()
  File "env/lib/python3.8/site-packages/pymysql/connections.py", line 725, in _read_packet
    packet.raise_for_error()
  File "env/lib/python3.8/site-packages/pymysql/protocol.py", line 221, in raise_for_error
    err.raise_mysql_exception(self._data)
  File "env/lib/python3.8/site-packages/pymysql/err.py", line 143, in raise_mysql_exception
    raise errorclass(errno, errval)
pymysql.err.OperationalError: (1045, "Access denied for user '_11d5326f068ed36c'@'localhost' (using password: YES)")

Backup failed for Site testsite2.com. Database or site_config.json may be corrupted
Traceback (most recent call last):
  File "apps/frappe/frappe/commands/site.py", line 686, in backup
    odb = scheduled_backup(
  File "apps/frappe/frappe/utils/backups.py", line 538, in scheduled_backup
    odb = new_backup(
  File "apps/frappe/frappe/utils/backups.py", line 572, in new_backup
    odb = BackupGenerator(
  File "apps/frappe/frappe/utils/backups.py", line 86, in __init__
    self.setup_backup_tables()
  File "apps/frappe/frappe/utils/backups.py", line 120, in setup_backup_tables
    existing_tables = frappe.db.get_tables()
  File "apps/frappe/frappe/database/database.py", line 1013, in get_tables
    table_rows = self.sql(
  File "apps/frappe/frappe/database/database.py", line 161, in sql
    self.connect()
  File "apps/frappe/frappe/database/database.py", line 93, in connect
    self._conn = self.get_connection()
  File "apps/frappe/frappe/database/mariadb/database.py", line 88, in get_connection
    conn = pymysql.connect(
  File "env/lib/python3.8/site-packages/pymysql/connections.py", line 353, in __init__
    self.connect()
  File "env/lib/python3.8/site-packages/pymysql/connections.py", line 633, in connect
    self._request_authentication()
  File "env/lib/python3.8/site-packages/pymysql/connections.py", line 907, in _request_authentication
    auth_packet = self._read_packet()
  File "env/lib/python3.8/site-packages/pymysql/connections.py", line 725, in _read_packet
    packet.raise_for_error()
  File "env/lib/python3.8/site-packages/pymysql/protocol.py", line 221, in raise_for_error
    err.raise_mysql_exception(self._data)
  File "env/lib/python3.8/site-packages/pymysql/err.py", line 143, in raise_mysql_exception
    raise errorclass(errno, errval)
pymysql.err.OperationalError: (1045, "Access denied for user '_11d5326f068ed36c'@'localhost' (using password: YES)")

Backup failed for Site testsite3.com. Database or site_config.json may be corrupted
Traceback (most recent call last):
  File "apps/frappe/frappe/commands/site.py", line 686, in backup
    odb = scheduled_backup(
  File "apps/frappe/frappe/utils/backups.py", line 538, in scheduled_backup
    odb = new_backup(
  File "apps/frappe/frappe/utils/backups.py", line 572, in new_backup
    odb = BackupGenerator(
  File "apps/frappe/frappe/utils/backups.py", line 86, in __init__
    self.setup_backup_tables()
  File "apps/frappe/frappe/utils/backups.py", line 120, in setup_backup_tables
    existing_tables = frappe.db.get_tables()
  File "apps/frappe/frappe/database/database.py", line 1013, in get_tables
    table_rows = self.sql(
  File "apps/frappe/frappe/database/database.py", line 161, in sql
    self.connect()
  File "apps/frappe/frappe/database/database.py", line 93, in connect
    self._conn = self.get_connection()
  File "apps/frappe/frappe/database/mariadb/database.py", line 88, in get_connection
    conn = pymysql.connect(
  File "env/lib/python3.8/site-packages/pymysql/connections.py", line 353, in __init__
    self.connect()
  File "env/lib/python3.8/site-packages/pymysql/connections.py", line 633, in connect
    self._request_authentication()
  File "env/lib/python3.8/site-packages/pymysql/connections.py", line 907, in _request_authentication
    auth_packet = self._read_packet()
  File "env/lib/python3.8/site-packages/pymysql/connections.py", line 725, in _read_packet
    packet.raise_for_error()
  File "env/lib/python3.8/site-packages/pymysql/protocol.py", line 221, in raise_for_error
    err.raise_mysql_exception(self._data)
  File "env/lib/python3.8/site-packages/pymysql/err.py", line 143, in raise_mysql_exception
    raise errorclass(errno, errval)
pymysql.err.OperationalError: (1045, "Access denied for user '_11d5326f068ed36c'@'localhost' (using password: YES)")

Backup failed for Site glbalbrands.com. Database or site_config.json may be corrupted
Traceback (most recent call last):
  File "apps/frappe/frappe/commands/site.py", line 686, in backup
    odb = scheduled_backup(
  File "apps/frappe/frappe/utils/backups.py", line 538, in scheduled_backup
    odb = new_backup(
  File "apps/frappe/frappe/utils/backups.py", line 572, in new_backup
    odb = BackupGenerator(
  File "apps/frappe/frappe/utils/backups.py", line 86, in __init__
    self.setup_backup_tables()
  File "apps/frappe/frappe/utils/backups.py", line 120, in setup_backup_tables
    existing_tables = frappe.db.get_tables()
  File "apps/frappe/frappe/database/database.py", line 1013, in get_tables
    table_rows = self.sql(
  File "apps/frappe/frappe/database/database.py", line 161, in sql
    self.connect()
  File "apps/frappe/frappe/database/database.py", line 93, in connect
    self._conn = self.get_connection()
  File "apps/frappe/frappe/database/mariadb/database.py", line 88, in get_connection
    conn = pymysql.connect(
  File "env/lib/python3.8/site-packages/pymysql/connections.py", line 353, in __init__
    self.connect()
  File "env/lib/python3.8/site-packages/pymysql/connections.py", line 633, in connect
    self._request_authentication()
  File "env/lib/python3.8/site-packages/pymysql/connections.py", line 907, in _request_authentication
    auth_packet = self._read_packet()
  File "env/lib/python3.8/site-packages/pymysql/connections.py", line 725, in _read_packet
    packet.raise_for_error()
  File "env/lib/python3.8/site-packages/pymysql/protocol.py", line 221, in raise_for_error
    err.raise_mysql_exception(self._data)
  File "env/lib/python3.8/site-packages/pymysql/err.py", line 143, in raise_mysql_exception
    raise errorclass(errno, errval)
pymysql.err.OperationalError: (1045, "Access denied for user '_11d5326f068ed36c'@'localhost' (using password: YES)")

Backup failed for Site globalbrands.com. Database or site_config.json may be corrupted
Traceback (most recent call last):
  File "apps/frappe/frappe/commands/site.py", line 686, in backup
    odb = scheduled_backup(
  File "apps/frappe/frappe/utils/backups.py", line 538, in scheduled_backup
    odb = new_backup(
  File "apps/frappe/frappe/utils/backups.py", line 572, in new_backup
    odb = BackupGenerator(
  File "apps/frappe/frappe/utils/backups.py", line 86, in __init__
    self.setup_backup_tables()
  File "apps/frappe/frappe/utils/backups.py", line 120, in setup_backup_tables
    existing_tables = frappe.db.get_tables()
  File "apps/frappe/frappe/database/database.py", line 1013, in get_tables
    table_rows = self.sql(
  File "apps/frappe/frappe/database/database.py", line 161, in sql
    self.connect()
  File "apps/frappe/frappe/database/database.py", line 93, in connect
    self._conn = self.get_connection()
  File "apps/frappe/frappe/database/mariadb/database.py", line 88, in get_connection
    conn = pymysql.connect(
  File "env/lib/python3.8/site-packages/pymysql/connections.py", line 353, in __init__
    self.connect()
  File "env/lib/python3.8/site-packages/pymysql/connections.py", line 633, in connect
    self._request_authentication()
  File "env/lib/python3.8/site-packages/pymysql/connections.py", line 907, in _request_authentication
    auth_packet = self._read_packet()
  File "env/lib/python3.8/site-packages/pymysql/connections.py", line 725, in _read_packet
    packet.raise_for_error()
  File "env/lib/python3.8/site-packages/pymysql/protocol.py", line 221, in raise_for_error
    err.raise_mysql_exception(self._data)
  File "env/lib/python3.8/site-packages/pymysql/err.py", line 143, in raise_mysql_exception
    raise errorclass(errno, errval)
pymysql.err.OperationalError: (1045, "Access denied for user '_11d5326f068ed36c'@'localhost' (using password: YES)")

Backup failed for Site mysite.com. Database or site_config.json may be corrupted
Traceback (most recent call last):
  File "apps/frappe/frappe/commands/site.py", line 686, in backup
    odb = scheduled_backup(
  File "apps/frappe/frappe/utils/backups.py", line 538, in scheduled_backup
    odb = new_backup(
  File "apps/frappe/frappe/utils/backups.py", line 572, in new_backup
    odb = BackupGenerator(
  File "apps/frappe/frappe/utils/backups.py", line 86, in __init__
    self.setup_backup_tables()
  File "apps/frappe/frappe/utils/backups.py", line 120, in setup_backup_tables
    existing_tables = frappe.db.get_tables()
  File "apps/frappe/frappe/database/database.py", line 1013, in get_tables
    table_rows = self.sql(
  File "apps/frappe/frappe/database/database.py", line 161, in sql
    self.connect()
  File "apps/frappe/frappe/database/database.py", line 93, in connect
    self._conn = self.get_connection()
  File "apps/frappe/frappe/database/mariadb/database.py", line 88, in get_connection
    conn = pymysql.connect(
  File "env/lib/python3.8/site-packages/pymysql/connections.py", line 353, in __init__
    self.connect()
  File "env/lib/python3.8/site-packages/pymysql/connections.py", line 633, in connect
    self._request_authentication()
  File "env/lib/python3.8/site-packages/pymysql/connections.py", line 907, in _request_authentication
    auth_packet = self._read_packet()
  File "env/lib/python3.8/site-packages/pymysql/connections.py", line 725, in _read_packet
    packet.raise_for_error()
  File "env/lib/python3.8/site-packages/pymysql/protocol.py", line 221, in raise_for_error
    err.raise_mysql_exception(self._data)
  File "env/lib/python3.8/site-packages/pymysql/err.py", line 143, in raise_mysql_exception
    raise errorclass(errno, errval)
pymysql.err.OperationalError: (1045, "Access denied for user '_11d5326f068ed36c'@'localhost' (using password: YES)")

Backup failed for Site mysite.localhost. Database or site_config.json may be corrupted
Traceback (most recent call last):
  File "apps/frappe/frappe/commands/site.py", line 686, in backup
    odb = scheduled_backup(
  File "apps/frappe/frappe/utils/backups.py", line 538, in scheduled_backup
    odb = new_backup(
  File "apps/frappe/frappe/utils/backups.py", line 572, in new_backup
    odb = BackupGenerator(
  File "apps/frappe/frappe/utils/backups.py", line 86, in __init__
    self.setup_backup_tables()
  File "apps/frappe/frappe/utils/backups.py", line 120, in setup_backup_tables
    existing_tables = frappe.db.get_tables()
  File "apps/frappe/frappe/database/database.py", line 1013, in get_tables
    table_rows = self.sql(
  File "apps/frappe/frappe/database/database.py", line 161, in sql
    self.connect()
  File "apps/frappe/frappe/database/database.py", line 93, in connect
    self._conn = self.get_connection()
  File "apps/frappe/frappe/database/mariadb/database.py", line 88, in get_connection
    conn = pymysql.connect(
  File "env/lib/python3.8/site-packages/pymysql/connections.py", line 353, in __init__
    self.connect()
  File "env/lib/python3.8/site-packages/pymysql/connections.py", line 633, in connect
    self._request_authentication()
  File "env/lib/python3.8/site-packages/pymysql/connections.py", line 907, in _request_authentication
    auth_packet = self._read_packet()
  File "env/lib/python3.8/site-packages/pymysql/connections.py", line 725, in _read_packet
    packet.raise_for_error()
  File "env/lib/python3.8/site-packages/pymysql/protocol.py", line 221, in raise_for_error
    err.raise_mysql_exception(self._data)
  File "env/lib/python3.8/site-packages/pymysql/err.py", line 143, in raise_mysql_exception
    raise errorclass(errno, errval)
pymysql.err.OperationalError: (1045, "Access denied for user '_11d5326f068ed36c'@'localhost' (using password: YES)")

Backup failed for Site testsite.com. Database or site_config.json may be corrupted
Traceback (most recent call last):
  File "apps/frappe/frappe/commands/site.py", line 686, in backup
    odb = scheduled_backup(
  File "apps/frappe/frappe/utils/backups.py", line 538, in scheduled_backup
    odb = new_backup(
  File "apps/frappe/frappe/utils/backups.py", line 572, in new_backup
    odb = BackupGenerator(
  File "apps/frappe/frappe/utils/backups.py", line 86, in __init__
    self.setup_backup_tables()
  File "apps/frappe/frappe/utils/backups.py", line 120, in setup_backup_tables
    existing_tables = frappe.db.get_tables()
  File "apps/frappe/frappe/database/database.py", line 1013, in get_tables
    table_rows = self.sql(
  File "apps/frappe/frappe/database/database.py", line 161, in sql
    self.connect()
  File "apps/frappe/frappe/database/database.py", line 93, in connect
    self._conn = self.get_connection()
  File "apps/frappe/frappe/database/mariadb/database.py", line 88, in get_connection
    conn = pymysql.connect(
  File "env/lib/python3.8/site-packages/pymysql/connections.py", line 353, in __init__
    self.connect()
  File "env/lib/python3.8/site-packages/pymysql/connections.py", line 633, in connect
    self._request_authentication()
  File "env/lib/python3.8/site-packages/pymysql/connections.py", line 907, in _request_authentication
    auth_packet = self._read_packet()
  File "env/lib/python3.8/site-packages/pymysql/connections.py", line 725, in _read_packet
    packet.raise_for_error()
  File "env/lib/python3.8/site-packages/pymysql/protocol.py", line 221, in raise_for_error
    err.raise_mysql_exception(self._data)
  File "env/lib/python3.8/site-packages/pymysql/err.py", line 143, in raise_mysql_exception
    raise errorclass(errno, errval)
pymysql.err.OperationalError: (1045, "Access denied for user '_11d5326f068ed36c'@'localhost' (using password: YES)")

Backup failed for Site testsite2.com. Database or site_config.json may be corrupted
Traceback (most recent call last):
  File "apps/frappe/frappe/commands/site.py", line 686, in backup
    odb = scheduled_backup(
  File "apps/frappe/frappe/utils/backups.py", line 538, in scheduled_backup
    odb = new_backup(
  File "apps/frappe/frappe/utils/backups.py", line 572, in new_backup
    odb = BackupGenerator(
  File "apps/frappe/frappe/utils/backups.py", line 86, in __init__
    self.setup_backup_tables()
  File "apps/frappe/frappe/utils/backups.py", line 120, in setup_backup_tables
    existing_tables = frappe.db.get_tables()
  File "apps/frappe/frappe/database/database.py", line 1013, in get_tables
    table_rows = self.sql(
  File "apps/frappe/frappe/database/database.py", line 161, in sql
    self.connect()
  File "apps/frappe/frappe/database/database.py", line 93, in connect
    self._conn = self.get_connection()
  File "apps/frappe/frappe/database/mariadb/database.py", line 88, in get_connection
    conn = pymysql.connect(
  File "env/lib/python3.8/site-packages/pymysql/connections.py", line 353, in __init__
    self.connect()
  File "env/lib/python3.8/site-packages/pymysql/connections.py", line 633, in connect
    self._request_authentication()
  File "env/lib/python3.8/site-packages/pymysql/connections.py", line 907, in _request_authentication
    auth_packet = self._read_packet()
  File "env/lib/python3.8/site-packages/pymysql/connections.py", line 725, in _read_packet
    packet.raise_for_error()
  File "env/lib/python3.8/site-packages/pymysql/protocol.py", line 221, in raise_for_error
    err.raise_mysql_exception(self._data)
  File "env/lib/python3.8/site-packages/pymysql/err.py", line 143, in raise_mysql_exception
    raise errorclass(errno, errval)
pymysql.err.OperationalError: (1045, "Access denied for user '_11d5326f068ed36c'@'localhost' (using password: YES)")

Backup failed for Site testsite3.com. Database or site_config.json may be corrupted
Traceback (most recent call last):
  File "apps/frappe/frappe/commands/site.py", line 686, in backup
    odb = scheduled_backup(
  File "apps/frappe/frappe/utils/backups.py", line 538, in scheduled_backup
    odb = new_backup(
  File "apps/frappe/frappe/utils/backups.py", line 572, in new_backup
    odb = BackupGenerator(
  File "apps/frappe/frappe/utils/backups.py", line 86, in __init__
    self.setup_backup_tables()
  File "apps/frappe/frappe/utils/backups.py", line 120, in setup_backup_tables
    existing_tables = frappe.db.get_tables()
  File "apps/frappe/frappe/database/database.py", line 1013, in get_tables
    table_rows = self.sql(
  File "apps/frappe/frappe/database/database.py", line 161, in sql
    self.connect()
  File "apps/frappe/frappe/database/database.py", line 93, in connect
    self._conn = self.get_connection()
  File "apps/frappe/frappe/database/mariadb/database.py", line 88, in get_connection
    conn = pymysql.connect(
  File "env/lib/python3.8/site-packages/pymysql/connections.py", line 353, in __init__
    self.connect()
  File "env/lib/python3.8/site-packages/pymysql/connections.py", line 633, in connect
    self._request_authentication()
  File "env/lib/python3.8/site-packages/pymysql/connections.py", line 907, in _request_authentication
    auth_packet = self._read_packet()
  File "env/lib/python3.8/site-packages/pymysql/connections.py", line 725, in _read_packet
    packet.raise_for_error()
  File "env/lib/python3.8/site-packages/pymysql/protocol.py", line 221, in raise_for_error
    err.raise_mysql_exception(self._data)
  File "env/lib/python3.8/site-packages/pymysql/err.py", line 143, in raise_mysql_exception
    raise errorclass(errno, errval)
pymysql.err.OperationalError: (1045, "Access denied for user '_11d5326f068ed36c'@'localhost' (using password: YES)")

Backup failed for Site glbalbrands.com. Database or site_config.json may be corrupted
Traceback (most recent call last):
  File "apps/frappe/frappe/commands/site.py", line 686, in backup
    odb = scheduled_backup(
  File "apps/frappe/frappe/utils/backups.py", line 538, in scheduled_backup
    odb = new_backup(
  File "apps/frappe/frappe/utils/backups.py", line 572, in new_backup
    odb = BackupGenerator(
  File "apps/frappe/frappe/utils/backups.py", line 86, in __init__
    self.setup_backup_tables()
  File "apps/frappe/frappe/utils/backups.py", line 120, in setup_backup_tables
    existing_tables = frappe.db.get_tables()
  File "apps/frappe/frappe/database/database.py", line 1013, in get_tables
    table_rows = self.sql(
  File "apps/frappe/frappe/database/database.py", line 161, in sql
    self.connect()
  File "apps/frappe/frappe/database/database.py", line 93, in connect
    self._conn = self.get_connection()
  File "apps/frappe/frappe/database/mariadb/database.py", line 88, in get_connection
    conn = pymysql.connect(
  File "env/lib/python3.8/site-packages/pymysql/connections.py", line 353, in __init__
    self.connect()
  File "env/lib/python3.8/site-packages/pymysql/connections.py", line 633, in connect
    self._request_authentication()
  File "env/lib/python3.8/site-packages/pymysql/connections.py", line 907, in _request_authentication
    auth_packet = self._read_packet()
  File "env/lib/python3.8/site-packages/pymysql/connections.py", line 725, in _read_packet
    packet.raise_for_error()
  File "env/lib/python3.8/site-packages/pymysql/protocol.py", line 221, in raise_for_error
    err.raise_mysql_exception(self._data)
  File "env/lib/python3.8/site-packages/pymysql/err.py", line 143, in raise_mysql_exception
    raise errorclass(errno, errval)
pymysql.err.OperationalError: (1045, "Access denied for user '_11d5326f068ed36c'@'localhost' (using password: YES)")

Backup failed for Site globalbrands.com. Database or site_config.json may be corrupted
Traceback (most recent call last):
  File "apps/frappe/frappe/commands/site.py", line 686, in backup
    odb = scheduled_backup(
  File "apps/frappe/frappe/utils/backups.py", line 538, in scheduled_backup
    odb = new_backup(
  File "apps/frappe/frappe/utils/backups.py", line 572, in new_backup
    odb = BackupGenerator(
  File "apps/frappe/frappe/utils/backups.py", line 86, in __init__
    self.setup_backup_tables()
  File "apps/frappe/frappe/utils/backups.py", line 120, in setup_backup_tables
    existing_tables = frappe.db.get_tables()
  File "apps/frappe/frappe/database/database.py", line 1013, in get_tables
    table_rows = self.sql(
  File "apps/frappe/frappe/database/database.py", line 161, in sql
    self.connect()
  File "apps/frappe/frappe/database/database.py", line 93, in connect
    self._conn = self.get_connection()
  File "apps/frappe/frappe/database/mariadb/database.py", line 88, in get_connection
    conn = pymysql.connect(
  File "env/lib/python3.8/site-packages/pymysql/connections.py", line 353, in __init__
    self.connect()
  File "env/lib/python3.8/site-packages/pymysql/connections.py", line 633, in connect
    self._request_authentication()
  File "env/lib/python3.8/site-packages/pymysql/connections.py", line 907, in _request_authentication
    auth_packet = self._read_packet()
  File "env/lib/python3.8/site-packages/pymysql/connections.py", line 725, in _read_packet
    packet.raise_for_error()
  File "env/lib/python3.8/site-packages/pymysql/protocol.py", line 221, in raise_for_error
    err.raise_mysql_exception(self._data)
  File "env/lib/python3.8/site-packages/pymysql/err.py", line 143, in raise_mysql_exception
    raise errorclass(errno, errval)
pymysql.err.OperationalError: (1045, "Access denied for user '_11d5326f068ed36c'@'localhost' (using password: YES)")

Backup failed for Site mysite.com. Database or site_config.json may be corrupted
Traceback (most recent call last):
  File "apps/frappe/frappe/commands/site.py", line 686, in backup
    odb = scheduled_backup(
  File "apps/frappe/frappe/utils/backups.py", line 538, in scheduled_backup
    odb = new_backup(
  File "apps/frappe/frappe/utils/backups.py", line 572, in new_backup
    odb = BackupGenerator(
  File "apps/frappe/frappe/utils/backups.py", line 86, in __init__
    self.setup_backup_tables()
  File "apps/frappe/frappe/utils/backups.py", line 120, in setup_backup_tables
    existing_tables = frappe.db.get_tables()
  File "apps/frappe/frappe/database/database.py", line 1013, in get_tables
    table_rows = self.sql(
  File "apps/frappe/frappe/database/database.py", line 161, in sql
    self.connect()
  File "apps/frappe/frappe/database/database.py", line 93, in connect
    self._conn = self.get_connection()
  File "apps/frappe/frappe/database/mariadb/database.py", line 88, in get_connection
    conn = pymysql.connect(
  File "env/lib/python3.8/site-packages/pymysql/connections.py", line 353, in __init__
    self.connect()
  File "env/lib/python3.8/site-packages/pymysql/connections.py", line 633, in connect
    self._request_authentication()
  File "env/lib/python3.8/site-packages/pymysql/connections.py", line 907, in _request_authentication
    auth_packet = self._read_packet()
  File "env/lib/python3.8/site-packages/pymysql/connections.py", line 725, in _read_packet
    packet.raise_for_error()
  File "env/lib/python3.8/site-packages/pymysql/protocol.py", line 221, in raise_for_error
    err.raise_mysql_exception(self._data)
  File "env/lib/python3.8/site-packages/pymysql/err.py", line 143, in raise_mysql_exception
    raise errorclass(errno, errval)
pymysql.err.OperationalError: (1045, "Access denied for user '_11d5326f068ed36c'@'localhost' (using password: YES)")

Backup failed for Site mysite.localhost. Database or site_config.json may be corrupted
Traceback (most recent call last):
  File "apps/frappe/frappe/commands/site.py", line 686, in backup
    odb = scheduled_backup(
  File "apps/frappe/frappe/utils/backups.py", line 538, in scheduled_backup
    odb = new_backup(
  File "apps/frappe/frappe/utils/backups.py", line 572, in new_backup
    odb = BackupGenerator(
  File "apps/frappe/frappe/utils/backups.py", line 86, in __init__
    self.setup_backup_tables()
  File "apps/frappe/frappe/utils/backups.py", line 120, in setup_backup_tables
    existing_tables = frappe.db.get_tables()
  File "apps/frappe/frappe/database/database.py", line 1013, in get_tables
    table_rows = self.sql(
  File "apps/frappe/frappe/database/database.py", line 161, in sql
    self.connect()
  File "apps/frappe/frappe/database/database.py", line 93, in connect
    self._conn = self.get_connection()
  File "apps/frappe/frappe/database/mariadb/database.py", line 88, in get_connection
    conn = pymysql.connect(
  File "env/lib/python3.8/site-packages/pymysql/connections.py", line 353, in __init__
    self.connect()
  File "env/lib/python3.8/site-packages/pymysql/connections.py", line 633, in connect
    self._request_authentication()
  File "env/lib/python3.8/site-packages/pymysql/connections.py", line 907, in _request_authentication
    auth_packet = self._read_packet()
  File "env/lib/python3.8/site-packages/pymysql/connections.py", line 725, in _read_packet
    packet.raise_for_error()
  File "env/lib/python3.8/site-packages/pymysql/protocol.py", line 221, in raise_for_error
    err.raise_mysql_exception(self._data)
  File "env/lib/python3.8/site-packages/pymysql/err.py", line 143, in raise_mysql_exception
    raise errorclass(errno, errval)
pymysql.err.OperationalError: (1045, "Access denied for user '_11d5326f068ed36c'@'localhost' (using password: YES)")

Backup failed for Site testsite.com. Database or site_config.json may be corrupted
Traceback (most recent call last):
  File "apps/frappe/frappe/commands/site.py", line 686, in backup
    odb = scheduled_backup(
  File "apps/frappe/frappe/utils/backups.py", line 538, in scheduled_backup
    odb = new_backup(
  File "apps/frappe/frappe/utils/backups.py", line 572, in new_backup
    odb = BackupGenerator(
  File "apps/frappe/frappe/utils/backups.py", line 86, in __init__
    self.setup_backup_tables()
  File "apps/frappe/frappe/utils/backups.py", line 120, in setup_backup_tables
    existing_tables = frappe.db.get_tables()
  File "apps/frappe/frappe/database/database.py", line 1013, in get_tables
    table_rows = self.sql(
  File "apps/frappe/frappe/database/database.py", line 161, in sql
    self.connect()
  File "apps/frappe/frappe/database/database.py", line 93, in connect
    self._conn = self.get_connection()
  File "apps/frappe/frappe/database/mariadb/database.py", line 88, in get_connection
    conn = pymysql.connect(
  File "env/lib/python3.8/site-packages/pymysql/connections.py", line 353, in __init__
    self.connect()
  File "env/lib/python3.8/site-packages/pymysql/connections.py", line 633, in connect
    self._request_authentication()
  File "env/lib/python3.8/site-packages/pymysql/connections.py", line 907, in _request_authentication
    auth_packet = self._read_packet()
  File "env/lib/python3.8/site-packages/pymysql/connections.py", line 725, in _read_packet
    packet.raise_for_error()
  File "env/lib/python3.8/site-packages/pymysql/protocol.py", line 221, in raise_for_error
    err.raise_mysql_exception(self._data)
  File "env/lib/python3.8/site-packages/pymysql/err.py", line 143, in raise_mysql_exception
    raise errorclass(errno, errval)
pymysql.err.OperationalError: (1045, "Access denied for user '_11d5326f068ed36c'@'localhost' (using password: YES)")

Backup failed for Site testsite2.com. Database or site_config.json may be corrupted
Traceback (most recent call last):
  File "apps/frappe/frappe/commands/site.py", line 686, in backup
    odb = scheduled_backup(
  File "apps/frappe/frappe/utils/backups.py", line 538, in scheduled_backup
    odb = new_backup(
  File "apps/frappe/frappe/utils/backups.py", line 572, in new_backup
    odb = BackupGenerator(
  File "apps/frappe/frappe/utils/backups.py", line 86, in __init__
    self.setup_backup_tables()
  File "apps/frappe/frappe/utils/backups.py", line 120, in setup_backup_tables
    existing_tables = frappe.db.get_tables()
  File "apps/frappe/frappe/database/database.py", line 1013, in get_tables
    table_rows = self.sql(
  File "apps/frappe/frappe/database/database.py", line 161, in sql
    self.connect()
  File "apps/frappe/frappe/database/database.py", line 93, in connect
    self._conn = self.get_connection()
  File "apps/frappe/frappe/database/mariadb/database.py", line 88, in get_connection
    conn = pymysql.connect(
  File "env/lib/python3.8/site-packages/pymysql/connections.py", line 353, in __init__
    self.connect()
  File "env/lib/python3.8/site-packages/pymysql/connections.py", line 633, in connect
    self._request_authentication()
  File "env/lib/python3.8/site-packages/pymysql/connections.py", line 907, in _request_authentication
    auth_packet = self._read_packet()
  File "env/lib/python3.8/site-packages/pymysql/connections.py", line 725, in _read_packet
    packet.raise_for_error()
  File "env/lib/python3.8/site-packages/pymysql/protocol.py", line 221, in raise_for_error
    err.raise_mysql_exception(self._data)
  File "env/lib/python3.8/site-packages/pymysql/err.py", line 143, in raise_mysql_exception
    raise errorclass(errno, errval)
pymysql.err.OperationalError: (1045, "Access denied for user '_11d5326f068ed36c'@'localhost' (using password: YES)")

Backup failed for Site testsite3.com. Database or site_config.json may be corrupted
Traceback (most recent call last):
  File "apps/frappe/frappe/commands/site.py", line 686, in backup
    odb = scheduled_backup(
  File "apps/frappe/frappe/utils/backups.py", line 538, in scheduled_backup
    odb = new_backup(
  File "apps/frappe/frappe/utils/backups.py", line 572, in new_backup
    odb = BackupGenerator(
  File "apps/frappe/frappe/utils/backups.py", line 86, in __init__
    self.setup_backup_tables()
  File "apps/frappe/frappe/utils/backups.py", line 120, in setup_backup_tables
    existing_tables = frappe.db.get_tables()
  File "apps/frappe/frappe/database/database.py", line 1013, in get_tables
    table_rows = self.sql(
  File "apps/frappe/frappe/database/database.py", line 161, in sql
    self.connect()
  File "apps/frappe/frappe/database/database.py", line 93, in connect
    self._conn = self.get_connection()
  File "apps/frappe/frappe/database/mariadb/database.py", line 88, in get_connection
    conn = pymysql.connect(
  File "env/lib/python3.8/site-packages/pymysql/connections.py", line 353, in __init__
    self.connect()
  File "env/lib/python3.8/site-packages/pymysql/connections.py", line 633, in connect
    self._request_authentication()
  File "env/lib/python3.8/site-packages/pymysql/connections.py", line 907, in _request_authentication
    auth_packet = self._read_packet()
  File "env/lib/python3.8/site-packages/pymysql/connections.py", line 725, in _read_packet
    packet.raise_for_error()
  File "env/lib/python3.8/site-packages/pymysql/protocol.py", line 221, in raise_for_error
    err.raise_mysql_exception(self._data)
  File "env/lib/python3.8/site-packages/pymysql/err.py", line 143, in raise_mysql_exception
    raise errorclass(errno, errval)
pymysql.err.OperationalError: (1045, "Access denied for user '_11d5326f068ed36c'@'localhost' (using password: YES)")

Backup failed for Site glbalbrands.com. Database or site_config.json may be corrupted
Traceback (most recent call last):
  File "apps/frappe/frappe/commands/site.py", line 686, in backup
    odb = scheduled_backup(
  File "apps/frappe/frappe/utils/backups.py", line 538, in scheduled_backup
    odb = new_backup(
  File "apps/frappe/frappe/utils/backups.py", line 572, in new_backup
    odb = BackupGenerator(
  File "apps/frappe/frappe/utils/backups.py", line 86, in __init__
    self.setup_backup_tables()
  File "apps/frappe/frappe/utils/backups.py", line 120, in setup_backup_tables
    existing_tables = frappe.db.get_tables()
  File "apps/frappe/frappe/database/database.py", line 1013, in get_tables
    table_rows = self.sql(
  File "apps/frappe/frappe/database/database.py", line 161, in sql
    self.connect()
  File "apps/frappe/frappe/database/database.py", line 93, in connect
    self._conn = self.get_connection()
  File "apps/frappe/frappe/database/mariadb/database.py", line 88, in get_connection
    conn = pymysql.connect(
  File "env/lib/python3.8/site-packages/pymysql/connections.py", line 353, in __init__
    self.connect()
  File "env/lib/python3.8/site-packages/pymysql/connections.py", line 633, in connect
    self._request_authentication()
  File "env/lib/python3.8/site-packages/pymysql/connections.py", line 907, in _request_authentication
    auth_packet = self._read_packet()
  File "env/lib/python3.8/site-packages/pymysql/connections.py", line 725, in _read_packet
    packet.raise_for_error()
  File "env/lib/python3.8/site-packages/pymysql/protocol.py", line 221, in raise_for_error
    err.raise_mysql_exception(self._data)
  File "env/lib/python3.8/site-packages/pymysql/err.py", line 143, in raise_mysql_exception
    raise errorclass(errno, errval)
pymysql.err.OperationalError: (1045, "Access denied for user '_11d5326f068ed36c'@'localhost' (using password: YES)")

Backup failed for Site globalbrands.com. Database or site_config.json may be corrupted
Traceback (most recent call last):
  File "apps/frappe/frappe/commands/site.py", line 686, in backup
    odb = scheduled_backup(
  File "apps/frappe/frappe/utils/backups.py", line 538, in scheduled_backup
    odb = new_backup(
  File "apps/frappe/frappe/utils/backups.py", line 572, in new_backup
    odb = BackupGenerator(
  File "apps/frappe/frappe/utils/backups.py", line 86, in __init__
    self.setup_backup_tables()
  File "apps/frappe/frappe/utils/backups.py", line 120, in setup_backup_tables
    existing_tables = frappe.db.get_tables()
  File "apps/frappe/frappe/database/database.py", line 1013, in get_tables
    table_rows = self.sql(
  File "apps/frappe/frappe/database/database.py", line 161, in sql
    self.connect()
  File "apps/frappe/frappe/database/database.py", line 93, in connect
    self._conn = self.get_connection()
  File "apps/frappe/frappe/database/mariadb/database.py", line 88, in get_connection
    conn = pymysql.connect(
  File "env/lib/python3.8/site-packages/pymysql/connections.py", line 353, in __init__
    self.connect()
  File "env/lib/python3.8/site-packages/pymysql/connections.py", line 633, in connect
    self._request_authentication()
  File "env/lib/python3.8/site-packages/pymysql/connections.py", line 907, in _request_authentication
    auth_packet = self._read_packet()
  File "env/lib/python3.8/site-packages/pymysql/connections.py", line 725, in _read_packet
    packet.raise_for_error()
  File "env/lib/python3.8/site-packages/pymysql/protocol.py", line 221, in raise_for_error
    err.raise_mysql_exception(self._data)
  File "env/lib/python3.8/site-packages/pymysql/err.py", line 143, in raise_mysql_exception
    raise errorclass(errno, errval)
pymysql.err.OperationalError: (1045, "Access denied for user '_11d5326f068ed36c'@'localhost' (using password: YES)")

Backup failed for Site mysite.com. Database or site_config.json may be corrupted
Traceback (most recent call last):
  File "apps/frappe/frappe/commands/site.py", line 686, in backup
    odb = scheduled_backup(
  File "apps/frappe/frappe/utils/backups.py", line 538, in scheduled_backup
    odb = new_backup(
  File "apps/frappe/frappe/utils/backups.py", line 572, in new_backup
    odb = BackupGenerator(
  File "apps/frappe/frappe/utils/backups.py", line 86, in __init__
    self.setup_backup_tables()
  File "apps/frappe/frappe/utils/backups.py", line 120, in setup_backup_tables
    existing_tables = frappe.db.get_tables()
  File "apps/frappe/frappe/database/database.py", line 1013, in get_tables
    table_rows = self.sql(
  File "apps/frappe/frappe/database/database.py", line 161, in sql
    self.connect()
  File "apps/frappe/frappe/database/database.py", line 93, in connect
    self._conn = self.get_connection()
  File "apps/frappe/frappe/database/mariadb/database.py", line 88, in get_connection
    conn = pymysql.connect(
  File "env/lib/python3.8/site-packages/pymysql/connections.py", line 353, in __init__
    self.connect()
  File "env/lib/python3.8/site-packages/pymysql/connections.py", line 633, in connect
    self._request_authentication()
  File "env/lib/python3.8/site-packages/pymysql/connections.py", line 907, in _request_authentication
    auth_packet = self._read_packet()
  File "env/lib/python3.8/site-packages/pymysql/connections.py", line 725, in _read_packet
    packet.raise_for_error()
  File "env/lib/python3.8/site-packages/pymysql/protocol.py", line 221, in raise_for_error
    err.raise_mysql_exception(self._data)
  File "env/lib/python3.8/site-packages/pymysql/err.py", line 143, in raise_mysql_exception
    raise errorclass(errno, errval)
pymysql.err.OperationalError: (1045, "Access denied for user '_11d5326f068ed36c'@'localhost' (using password: YES)")

Backup failed for Site mysite.localhost. Database or site_config.json may be corrupted
Traceback (most recent call last):
  File "apps/frappe/frappe/commands/site.py", line 686, in backup
    odb = scheduled_backup(
  File "apps/frappe/frappe/utils/backups.py", line 538, in scheduled_backup
    odb = new_backup(
  File "apps/frappe/frappe/utils/backups.py", line 572, in new_backup
    odb = BackupGenerator(
  File "apps/frappe/frappe/utils/backups.py", line 86, in __init__
    self.setup_backup_tables()
  File "apps/frappe/frappe/utils/backups.py", line 120, in setup_backup_tables
    existing_tables = frappe.db.get_tables()
  File "apps/frappe/frappe/database/database.py", line 1013, in get_tables
    table_rows = self.sql(
  File "apps/frappe/frappe/database/database.py", line 161, in sql
    self.connect()
  File "apps/frappe/frappe/database/database.py", line 93, in connect
    self._conn = self.get_connection()
  File "apps/frappe/frappe/database/mariadb/database.py", line 88, in get_connection
    conn = pymysql.connect(
  File "env/lib/python3.8/site-packages/pymysql/connections.py", line 353, in __init__
    self.connect()
  File "env/lib/python3.8/site-packages/pymysql/connections.py", line 633, in connect
    self._request_authentication()
  File "env/lib/python3.8/site-packages/pymysql/connections.py", line 907, in _request_authentication
    auth_packet = self._read_packet()
  File "env/lib/python3.8/site-packages/pymysql/connections.py", line 725, in _read_packet
    packet.raise_for_error()
  File "env/lib/python3.8/site-packages/pymysql/protocol.py", line 221, in raise_for_error
    err.raise_mysql_exception(self._data)
  File "env/lib/python3.8/site-packages/pymysql/err.py", line 143, in raise_mysql_exception
    raise errorclass(errno, errval)
pymysql.err.OperationalError: (1045, "Access denied for user '_11d5326f068ed36c'@'localhost' (using password: YES)")

Backup failed for Site testsite.com. Database or site_config.json may be corrupted
Traceback (most recent call last):
  File "apps/frappe/frappe/commands/site.py", line 686, in backup
    odb = scheduled_backup(
  File "apps/frappe/frappe/utils/backups.py", line 538, in scheduled_backup
    odb = new_backup(
  File "apps/frappe/frappe/utils/backups.py", line 572, in new_backup
    odb = BackupGenerator(
  File "apps/frappe/frappe/utils/backups.py", line 86, in __init__
    self.setup_backup_tables()
  File "apps/frappe/frappe/utils/backups.py", line 120, in setup_backup_tables
    existing_tables = frappe.db.get_tables()
  File "apps/frappe/frappe/database/database.py", line 1013, in get_tables
    table_rows = self.sql(
  File "apps/frappe/frappe/database/database.py", line 161, in sql
    self.connect()
  File "apps/frappe/frappe/database/database.py", line 93, in connect
    self._conn = self.get_connection()
  File "apps/frappe/frappe/database/mariadb/database.py", line 88, in get_connection
    conn = pymysql.connect(
  File "env/lib/python3.8/site-packages/pymysql/connections.py", line 353, in __init__
    self.connect()
  File "env/lib/python3.8/site-packages/pymysql/connections.py", line 633, in connect
    self._request_authentication()
  File "env/lib/python3.8/site-packages/pymysql/connections.py", line 907, in _request_authentication
    auth_packet = self._read_packet()
  File "env/lib/python3.8/site-packages/pymysql/connections.py", line 725, in _read_packet
    packet.raise_for_error()
  File "env/lib/python3.8/site-packages/pymysql/protocol.py", line 221, in raise_for_error
    err.raise_mysql_exception(self._data)
  File "env/lib/python3.8/site-packages/pymysql/err.py", line 143, in raise_mysql_exception
    raise errorclass(errno, errval)
pymysql.err.OperationalError: (1045, "Access denied for user '_11d5326f068ed36c'@'localhost' (using password: YES)")

Backup failed for Site testsite2.com. Database or site_config.json may be corrupted
Traceback (most recent call last):
  File "apps/frappe/frappe/commands/site.py", line 686, in backup
    odb = scheduled_backup(
  File "apps/frappe/frappe/utils/backups.py", line 538, in scheduled_backup
    odb = new_backup(
  File "apps/frappe/frappe/utils/backups.py", line 572, in new_backup
    odb = BackupGenerator(
  File "apps/frappe/frappe/utils/backups.py", line 86, in __init__
    self.setup_backup_tables()
  File "apps/frappe/frappe/utils/backups.py", line 120, in setup_backup_tables
    existing_tables = frappe.db.get_tables()
  File "apps/frappe/frappe/database/database.py", line 1013, in get_tables
    table_rows = self.sql(
  File "apps/frappe/frappe/database/database.py", line 161, in sql
    self.connect()
  File "apps/frappe/frappe/database/database.py", line 93, in connect
    self._conn = self.get_connection()
  File "apps/frappe/frappe/database/mariadb/database.py", line 88, in get_connection
    conn = pymysql.connect(
  File "env/lib/python3.8/site-packages/pymysql/connections.py", line 353, in __init__
    self.connect()
  File "env/lib/python3.8/site-packages/pymysql/connections.py", line 633, in connect
    self._request_authentication()
  File "env/lib/python3.8/site-packages/pymysql/connections.py", line 907, in _request_authentication
    auth_packet = self._read_packet()
  File "env/lib/python3.8/site-packages/pymysql/connections.py", line 725, in _read_packet
    packet.raise_for_error()
  File "env/lib/python3.8/site-packages/pymysql/protocol.py", line 221, in raise_for_error
    err.raise_mysql_exception(self._data)
  File "env/lib/python3.8/site-packages/pymysql/err.py", line 143, in raise_mysql_exception
    raise errorclass(errno, errval)
pymysql.err.OperationalError: (1045, "Access denied for user '_11d5326f068ed36c'@'localhost' (using password: YES)")

Backup failed for Site testsite3.com. Database or site_config.json may be corrupted
Traceback (most recent call last):
  File "apps/frappe/frappe/commands/site.py", line 686, in backup
    odb = scheduled_backup(
  File "apps/frappe/frappe/utils/backups.py", line 538, in scheduled_backup
    odb = new_backup(
  File "apps/frappe/frappe/utils/backups.py", line 572, in new_backup
    odb = BackupGenerator(
  File "apps/frappe/frappe/utils/backups.py", line 86, in __init__
    self.setup_backup_tables()
  File "apps/frappe/frappe/utils/backups.py", line 120, in setup_backup_tables
    existing_tables = frappe.db.get_tables()
  File "apps/frappe/frappe/database/database.py", line 1013, in get_tables
    table_rows = self.sql(
  File "apps/frappe/frappe/database/database.py", line 161, in sql
    self.connect()
  File "apps/frappe/frappe/database/database.py", line 93, in connect
    self._conn = self.get_connection()
  File "apps/frappe/frappe/database/mariadb/database.py", line 88, in get_connection
    conn = pymysql.connect(
  File "env/lib/python3.8/site-packages/pymysql/connections.py", line 353, in __init__
    self.connect()
  File "env/lib/python3.8/site-packages/pymysql/connections.py", line 633, in connect
    self._request_authentication()
  File "env/lib/python3.8/site-packages/pymysql/connections.py", line 907, in _request_authentication
    auth_packet = self._read_packet()
  File "env/lib/python3.8/site-packages/pymysql/connections.py", line 725, in _read_packet
    packet.raise_for_error()
  File "env/lib/python3.8/site-packages/pymysql/protocol.py", line 221, in raise_for_error
    err.raise_mysql_exception(self._data)
  File "env/lib/python3.8/site-packages/pymysql/err.py", line 143, in raise_mysql_exception
    raise errorclass(errno, errval)
pymysql.err.OperationalError: (1045, "Access denied for user '_11d5326f068ed36c'@'localhost' (using password: YES)")

